Workbook

Sheet Couv
A24: Les Finances des
A25: communes en 2024
A33: Collection
A34: Statistiques et finances locales (tableaux)
A101: Les tableaux « Les finances des communes en 2024 »
A102: ont été élaborés au Département des études et des statistiques locales (DESL)
A103: de la Direction générale des collectivités locales (DGCL)
A104: par Guillaume LEFORESTIER
A106: janvier 2026
A108: Directrice de la publication : Cécile Raquin

Sheet Index
A2: Les finances des communes en 2024
C3: Mise en ligne : janvier 2026
B6: Département des Etudes et Statistiques Locales - DGCL
B7: https://www.collectivites-locales.gouv.fr/etudes-et-statistiques-locales
B9: ► | C9: T 1.1 | D9: : | E9: Répartition des communes par strate de population en 2024 | G9: 2
B10: ► | C10: T 1.2 | D10: : | E10: Répartition des communes et de leur population par région et strate de population | G10: 3
B11: ► | C11: T 1.3 | D11: : | E11: Répartition des communes appartenant à un groupement à fiscalité propre selon le type de groupement | G11: 6
B12: ► | C12: T 1.4 | D12: : | E12: Répartition des communes selon leur caractère touristique et de montagne par strate de population | G12: 7
B13: ► | C13: T 1.5 | D13: : | E13: Répartition des communes selon leur caractère urbain ou rural par strate de population | G13: 9
B14: ► | C14: T 2.1 | D14: : | E14: Comptes des communes par strate de population en 2024 | G14: 11
B15: ► | C15: T 2.2 | D15: : | E15: Les dépenses et recettes par habitant des communes par strate de population | G15: 14
B16: ► | C16: T 2.3 | D16: : | E16: Evolution 2024/2023 des comptes des communes par strate de population | G16: 16
B17: ► | C17: T 3 | D17: : | E17: Données financières des communes par strate de population selon leurs caractéristiques en 2024 | G17: 18
B18: ► | C18: T 4.1 | D18: : | E18: Données financières des communes touristiques par strate de population (France métropolitaine) | G18: 22
B19: ► | C19: T 4.2 | D19: : | E19: Données financières des communes touristiques du littoral maritime par strate de population (France métropolitaine) | G19: 26
B20: ► | C20: T 4.3 | D20: : | E20: Données financières des communes touristiques «supports de stations de sports d'hiver» par strate de population (France métropolitaine) | G20: 30
... B39: ► | C39: Annexe 3 | D39: : | E39: Définitions des ratios financiers obligatoires | G39: 111
C41: Abréviations : | E41: - M€ : millions d'€
E42: - n.s. : non-significatif
E43: - n.d. : non-disponible
C44: Symbole : | E44: - : néant

Sheet T 1.1
A1: T 1.1 - Répartition du nombre de communes (a) par strate de population communale en 2024
A4: Population totale au 1er janvier 2024 (millésimée 2021).
B6: Outre-Mer (b) | E6: France métropolitaine | H6: France entière (c)
B8: Nombre | C8: Population | D8: Population | E8: Nombre | F8: Population | G8: Population | H8: Nombre | I8: Population | J8: Population
A9: Strates | B9: de | C9: des communes | D9: moyenne | E9: de | F9: des communes | G9: moyenne | H9: de | I9: des communes | J9: moyenne
B10: budgets | C10: en milliers | D10: d'une | E10: budgets | F10: en milliers | G10: d'une | H10: budgets | I10: en milliers | J10: d'une
B11: communaux | C11: d'habitants | D11: commune | E11: communaux | F11: d'habitants | G11: commune | H11: communaux | I11: d'habitants | J11: commune
A12: Moins de 100 habitants | B12: - | C12: - | D12: - | E12: 3285 | F12: 213.108 | G12: =F12*1000/E12 -> 64.873059 | H12: =E12 -> 3285 | I12: =F12 -> 213.108 | J12: =I12*1000/H12 -> 64.873059
A13: De 100 à moins de 200 habitants | B13: - | C13: - | D13: - | E13: 5363 | F13: 790.955 | G13: =F13*1000/E13 -> 147.48368 | H13: =E13 -> 5363 | I13: =F13 -> 790.955 | J13: =I13*1000/H13 -> 147.48368
A14: De 200 à moins de 500 habitants | B14: 3 | C14: 0.821 | D14: =C14*1000/B14 -> 273.66667 | E14: 9463 | F14: 3081.382 | G14: =F14*1000/E14 -> 325.62422 | H14: =B14+E14 -> 9466 | I14: =C14+F14 -> 3082.203 | J14: =I14*1000/H14 -> 325.60775
A15: De 500 à moins de 2 000 habitants | B15: 13 | C15: 17.832 | D15: =C15*1000/B15 -> 1371.6923 | E15: 11240 | F15: 11089.396 | G15: =F15*1000/E15 -> 986.60107 | H15: =B15+E15 -> 11253 | I15: =C15+F15 -> 11107.228 | J15: =I15*1000/H15 -> 987.04594
A16: De 2 000 à moins de 3 500 habitants | B16: 9 | C16: 25.502 | D16: =C16*1000/B16 -> 2833.5556 | E16: 2289 | F16: 5996.337 | G16: =F16*1000/E16 -> 2619.6317 | H16: =B16+E16 -> 2298 | I16: =C16+F16 -> 6021.839 | J16: =I16*1000/H16 -> 2620.4695
A17: De 3 500 à moins de 5 000 habitants | B17: 10 | C17: 42.654 | D17: =C17*1000/B17 -> 4265.4 | E17: 986 | F17: 4104.341 | G17: =F17*1000/E17 -> 4162.6176 | H17: =B17+E17 -> 996 | I17: =C17+F17 -> 4146.995 | J17: =I17*1000/H17 -> 4163.6496
A18: De 5 000 à moins de 10 000 habitants | B18: 35 | C18: 257.774 | D18: =C18*1000/B18 -> 7364.9714 | E18: 1192 | F18: 8271.659 | G18: =F18*1000/E18 -> 6939.3112 | H18: =B18+E18 -> 1227 | I18: =C18+F18 -> 8529.433 | J18: =I18*1000/H18 -> 6951.4531
A19: De 10 000 à moins de 20 000 habitants | B19: 30 | C19: 430.586 | D19: =C19*1000/B19 -> 14352.867 | E19: 523 | F19: 7115.114 | G19: =F19*1000/E19 -> 13604.424 | H19: =B19+E19 -> 553 | I19: =C19+F19 -> 7545.7 | J19: =I19*1000/H19 -> 13645.027
A20: De 20 000 à moins de 50 000 habitants | B20: 18 | C20: 553.179 | D20: =C20*1000/B20 -> 30732.167 | E20: 343 | F20: 10405.522 | G20: =F20*1000/E20 -> 30336.799 | H20: =B20+E20 -> 361 | I20: =C20+F20 -> 10958.701 | J20: =I20*1000/H20 -> 30356.512
A21: De 50 000 à moins de 100 000 habitants | B21: 9 | C21: 595.518 | D21: =C21*1000/B21 -> 66168.667 | E21: 82 | F21: 5539.209 | G21: =F21*1000/E21 -> 67551.329 | H21: =B21+E21 -> 91 | I21: =C21+F21 -> 6134.727 | J21: =I21*1000/H21 -> 67414.582
A22: 100 000 habitants et plus | B22: 2 | C22: 262.836 | D22: =C22*1000/B22 -> 131418 | E22: 40 | F22: 10089.735 | G22: =F22*1000/E22 -> 252243.38 | H22: =B22+E22 -> 42 | I22: =C22+F22 -> 10352.571 | J22: =I22*1000/H22 -> 246489.79
A23: Communes de moins de 10 000 habitants | B23: 70 | C23: 344.583 | D23: =C23*1000/B23 -> 4922.6143 | E23: 33818 | F23: 33547.178 | G23: =F23*1000/E23 -> 991.99178 | H23: =B23+E23 -> 33888 | I23: =C23+F23 -> 33891.761 | J23: =I23*1000/H23 -> 1000.111
A24: Communes de 10 000 habitants et plus (y. c. Paris) | B24: 59 | C24: 1842.119 | D24: =C24*1000/B24 -> 31222.356 | E24: 988 | F24: 33149.58 | G24: =F24*1000/E24 -> 33552.206 | H24: =B24+E24 -> 1047 | I24: =C24+F24 -> 34991.699 | J24: =I24*1000/H24 -> 33420.916
A25: Ensemble des communes (y compris Paris) | B25: 129 | C25: 2186.702 | D25: =C25*1000/B25 -> 16951.178 | E25: 34806 | F25: 66696.758 | G25: =F25*1000/E25 -> 1916.2431 | H25: =B25+E25 -> 34935 | I25: =C25+F25 -> 68883.46 | J25: =I25*1000/H25 -> 1971.7607
A26: (a) Il s'agit, plus précisément, du nombre de budgets principaux de communes présents dans le fichier des comptes de gestion.
A27: (b) Il s'agit des 5 départements d'outre-mer (y compris Mayotte).
A28: (c) Ensemble constitué de la France métropolitaine et des départements d'outre-mer y compris Mayotte.
A29: Lecture : en France métropolitaine, il y a 11 240 communes dans la strate des 500 à 2000 habitants, qui regroupent 11,089 millions d'habitants pour une taille moyenne de 987 habitants.
A30: Source : INSEE, Recensement de la population (population totale en 2024 - année de référence 2021) ; calculs DGCL.

Sheet T 1.2
A1: T 1.2.a - Répartition du nombre de communes (a) par région et strate communale en 2024
N2: Nombre de communes(a)
B4: Moins | C4: De 100 | D4: De 200 | E4: De 500 | F4: De 2 000 | G4: De 3 500 | H4: De 5 000 | I4: De 10 000 | J4: De 20 000 | K4: De 50 000 | L4: 100000 | M4: Nombre de | N4: Nombre de | O4: Nombre total
A5: REGIONS | B5: de 100 | C5: à moins de | D5: à moins de | E5: à moins de | F5: à moins de | G5: à moins de | H5: à moins de | I5: à moins de | J5: à moins de | K5: à moins de | L5: habitants | M5: communes de | N5: communes de | O5: de
B6: habitants | C6: 200 hab. | D6: 500 hab. | E6: 2 000 hab. | F6: 3 500 hab. | G6: 5 000 hab. | H6: 10 000 hab. | I6: 20 000 hab. | J6: 50 000 hab. | K6: 100 000 hab. | L6: et plus | M6: moins de 10 000 hab. | N6: 10 000 hab. et plus | O6: communes
A8: Auvergne-Rhône-Alpes | B8: 256 | C8: 431 | D8: 931 | E8: 1631 | F8: 355 | G8: 137 | H8: 180 | I8: 63 | J8: 33 | K8: 4 | L8: 6 | M8: 3921 | N8: 106 | O8: 4027
A9: Bourgogne-Franche-Comté | B9: 587 | C9: 851 | D9: 1156 | E9: 894 | F9: 102 | G9: 37 | H9: 47 | I9: 11 | J9: 10 | K9: - | L9: 2 | M9: 3674 | N9: 23 | O9: 3697
A10: Bretagne | B10: 2 | C10: 23 | D10: 162 | E10: 580 | F10: 202 | G10: 104 | H10: 90 | I10: 31 | J10: 7 | K10: 3 | L10: 2 | M10: 1163 | N10: 43 | O10: 1206
A11: Centre-Val de Loire | B11: 56 | C11: 193 | D11: 579 | E11: 692 | F11: 112 | G11: 48 | H11: 42 | I11: 22 | J11: 9 | K11: 1 | L11: 2 | M11: 1722 | N11: 34 | O11: 1756
A12: Corse | B12: 119 | C12: 85 | D12: 59 | E12: 63 | F12: 19 | G12: 6 | H12: 6 | I12: 1 | J12: 1 | K12: 1 | L12: - | M12: 357 | N12: 3 | O12: 360
A13: Grand Est | B13: 844 | C13: 1041 | D13: 1394 | E13: 1346 | F13: 228 | G13: 89 | H13: 103 | I13: 50 | J13: 16 | K13: 2 | L13: 5 | M13: 5045 | N13: 73 | O13: 5118
A14: Hauts-de-France | B14: 257 | C14: 610 | D14: 1157 | E14: 1214 | F14: 229 | G14: 97 | H14: 122 | I14: 62 | J14: 31 | K14: 7 | L14: 2 | M14: 3686 | N14: 102 | O14: 3788
A15: Normandie | B15: 129 | C15: 398 | D15: 892 | E15: 936 | F15: 137 | G15: 64 | H15: 52 | I15: 27 | J15: 12 | K15: 1 | L15: 3 | M15: 2608 | N15: 43 | O15: 2651
A16: Nouvelle-Aquitaine | B16: 190 | C16: 650 | D16: 1343 | E16: 1559 | F16: 272 | G16: 95 | H16: 123 | I16: 37 | J16: 27 | K16: 7 | L16: 2 | M16: 4232 | N16: 73 | O16: 4305
A17: Occitanie | B17: 733 | C17: 858 | D17: 1198 | E17: 1117 | F17: 238 | G17: 107 | H17: 128 | I17: 47 | J17: 19 | K17: 4 | L17: 4 | M17: 4379 | N17: 74 | O17: 4453
A18: Pays de la Loire | B18: 11 | C18: 57 | D18: 214 | E18: 525 | F18: 194 | G18: 80 | H18: 96 | I18: 32 | J18: 15 | K18: 5 | L18: 3 | M18: 1177 | N18: 55 | O18: 1232
A19: Provence-Alpes-Côte d'Azur | B19: 87 | C19: 110 | D19: 169 | E19: 246 | F19: 91 | G19: 59 | H19: 90 | I19: 52 | J19: 30 | K19: 8 | L19: 4 | M19: 852 | N19: 94 | O19: 946
A20: Île-de-France | B20: 14 | C20: 56 | D20: 209 | E20: 437 | F20: 110 | G20: 63 | H20: 113 | I20: 88 | J20: 133 | K20: 39 | L20: 5 | M20: 1002 | N20: 265 | O20: 1267
A21: France métropolitaine | B21: =SUM(B8:B20) -> 3285 | C21: =SUM(C8:C20) -> 5363 | D21: =SUM(D8:D20) -> 9463 | E21: =SUM(E8:E20) -> 11240 | F21: =SUM(F8:F20) -> 2289 | G21: =SUM(G8:G20) -> 986 | H21: =SUM(H8:H20) -> 1192 | I21: =SUM(I8:I20) -> 523 | ... O21: =SUM(O8:O20) -> 34806
A22: Outre-Mer (b) | B22: - | C22: - | D22: 3 | E22: 13 | F22: 9 | G22: 10 | H22: 35 | I22: 30 | J22: 18 | K22: 9 | L22: 2 | M22: 70 | N22: 59 | O22: 129
A23: - dont Guadeloupe | B23: - | C23: - | D23: - | E23: 4 | F23: 2 | G23: 3 | H23: 10 | I23: 7 | J23: 5 | K23: 1 | L23: - | M23: 19 | N23: 13 | O23: 32
A24: - dont Martinique | B24: - | C24: - | D24: - | E24: 6 | F24: 3 | G24: 6 | H24: 7 | I24: 9 | J24: 2 | K24: 1 | L24: - | M24: 22 | N24: 12 | O24: 34
A25: - dont Guyane | B25: - | C25: - | D25: 3 | E25: 3 | F25: 4 | G25: 1 | H25: 4 | I25: 2 | J25: 3 | K25: 2 | L25: - | M25: 15 | N25: 7 | O25: 22
A26: - dont Réunion | B26: - | C26: - | D26: - | E26: - | F26: - | G26: - | H26: 7 | I26: 4 | J26: 7 | K26: 4 | L26: 2 | M26: 7 | N26: 17 | O26: 24
A27: - dont Mayotte | B27: - | C27: - | D27: - | E27: - | F27: - | G27: - | H27: 7 | I27: 8 | J27: 1 | K27: 1 | L27: - | M27: 7 | N27: 10 | O27: 17
A28: France entière | B28: =SUM(B21:B22) -> 3285 | C28: =SUM(C21:C22) -> 5363 | D28: =SUM(D21:D22) -> 9466 | E28: =SUM(E21:E22) -> 11253 | F28: =SUM(F21:F22) -> 2298 | G28: =SUM(G21:G22) -> 996 | H28: =SUM(H21:H22) -> 1227 | I28: =SUM(I21:I22) -> 553 | ... O28: =SUM(O21:O22) -> 34935
A29: (a) Il s'agit, plus précisément, du nombre de budgets principaux de communes.
A30: (b) Il s'agit des communes des 5 départements d'outre-mer (y compris Mayotte).
A31: Lecture: il y a 256 budgets principaux de communes de moins de 100 habitants en région Auvergne- Rhône-Alpes
A32: Source : INSEE, Recensement de la population (population totale en 2024 - année de référence 2021) ; calculs DGCL.
A34: T 1.2.b - Répartition de la population des communes par région et strate communale en 2024
A35: Habitants décomptés selon la population totale de l'Insee | N35: En milliers d'habitants
B37: Moins | C37: De 100 | D37: De 200 | E37: De 500 | F37: De 2 000 | G37: De 3 500 | H37: De 5 000 | I37: De 10 000 | J37: De 20 000 | K37: De 50 000 | L37: 100000 | M37: Population des | N37: Population des | O37: Population
A38: REGIONS | B38: de 100 | C38: à moins de | D38: à moins de | E38: à moins de | F38: à moins de | G38: à moins de | H38: à moins de | I38: à moins de | J38: à moins de | K38: à moins de | L38: habitants | M38: communes de | N38: communes de | O38: totale des
B39: habitants | C39: 200 hab. | D39: 500 hab. | E39: 2 000 hab. | F39: 3 500 hab. | G39: 5 000 hab. | H39: 10 000 hab. | I39: 20 000 hab. | J39: 50 000 hab. | K39: 100 000 hab. | L39: et plus | M39: moins de 10 000 hab. | N39: 10 000 hab. et plus | O39: communes
A41: Auvergne-Rhône-Alpes | B41: 15.69 | C41: 63.145 | D41: 308.998 | E41: 1670.478 | F41: 924.668 | G41: 567.247 | H41: 1263.212 | I41: 872 | J41: 1047.359 | K41: 246.057 | L41: 1305.308 | M41: 4813.438 | N41: 3470.724 | O41: 8284.162
A42: Bourgogne-Franche-Comté | B42: 38.977 | C42: 125.814 | D42: 371.666 | E42: 840.068 | F42: 264.729 | G42: 153.354 | H42: 317.793 | I42: 157.511 | J42: 317.361 | K42: - | L42: 285.113 | M42: 2112.401 | N42: 759.985 | O42: 2872.386
A43: Bretagne | B43: 0.156 | C43: 3.647 | D43: 57.018 | E43: 652.679 | F43: 525.358 | G43: 430.936 | H43: 633.519 | I43: 424.519 | J43: 201.741 | K43: 181.558 | L43: 371.412 | M43: 2303.313 | N43: 1179.23 | O43: 3482.543
A44: Centre-Val de Loire | B44: 4.003 | C44: 29.114 | D44: 189.938 | E44: 685.931 | F44: 297.258 | G44: 198.842 | H44: 299.131 | I44: 306.221 | J44: 295.401 | K44: 65.723 | L44: 259.181 | M44: 1704.217 | N44: 926.526 | O44: 2630.743
A45: Corse | B45: 6.596 | C45: 11.675 | D45: 17.94 | E45: 61.545 | F45: 52.338 | G45: 23.549 | H45: 43.526 | I45: 11.382 | J45: 49.376 | K45: 74.632 | L45: - | M45: 217.169 | N45: 135.39 | O45: 352.559
...

Sheet T 1.3
A1: T 1.3.a - Répartition des communes (a) appartenant à un groupement à fiscalité propre selon le type de groupement (b) en 2024
B4: Moins | C4: De 100 | D4: De 200 | E4: De 500 | F4: De 2 000 | G4: De 3 500 | H4: De 5 000 | I4: De 10 000 | J4: De 20 000 | K4: De 50 000 | L4: 100000 | M4: Budgets des | N4: Budgets des | O4: Ensemble
A5: Strate des communes | B5: de 100 | C5: à moins de | D5: à moins de | E5: à moins de | F5: à moins de | G5: à moins de | H5: à moins de | I5: à moins de | J5: à moins de | K5: à moins de | L5: habitants | M5: communes de moins | N5: communes de | O5: des
B6: habitants | C6: 200 hab. | D6: 500 hab. | E6: 2 000 hab. | F6: 3 500 hab. | G6: 5 000 hab. | H6: 10 000 hab. | I6: 20 000 hab. | J6: 50 000 hab. | K6: 100 000 hab. | L6: et plus | M6: de 10 000 hab. | N6: 10 000 hab. et plus | O6: budgets
A8: Nombre de communes appartenant à :
A9: CU ou métropoles(c) | B9: 11 | C9: 50 | D9: 139 | E9: 448 | F9: 198 | G9: 125 | H9: 266 | I9: 158 | J9: 155 | K9: 43 | L9: 36 | M9: 1237 | N9: 392 | O9: 1629
A10: CA | B10: 225 | C10: 546 | D10: 1595 | E10: 3066 | F10: 820 | G10: 366 | H10: 468 | I10: 250 | J10: 197 | K10: 47 | L10: 6 | M10: 7086 | N10: 500 | O10: 7586
A11: CC à FPU | B11: 2215 | C11: 3670 | D11: 6340 | E11: 6782 | F11: 1168 | G11: 457 | H11: 452 | I11: 137 | J11: 9 | K11: 1 | L11: - | M11: 21084 | N11: 147 | O11: 21231
A12: CC à FA | B12: 834 | C12: 1097 | D12: 1390 | E12: 956 | F12: 112 | G12: 48 | H12: 40 | I12: 8 | J12: - | K12: - | L12: - | M12: 4477 | N12: 8 | O12: 4485
A13: non membre d'un groupement fiscalisé | B13: - | C13: - | D13: 2 | E13: 1 | F13: - | G13: - | H13: 1 | I13: - | J13: - | K13: - | L13: - | M13: 4 | N13: - | O13: 4
A14: Total | B14: =SUM(B9:B13) -> 3285 | C14: =SUM(C9:C13) -> 5363 | D14: =SUM(D9:D13) -> 9466 | E14: =SUM(E9:E13) -> 11253 | F14: =SUM(F9:F13) -> 2298 | G14: =SUM(G9:G13) -> 996 | H14: =SUM(H9:H13) -> 1227 | I14: =SUM(I9:I13) -> 553 | ... O14: =SUM(O9:O13) -> 34935
A15: Pourcentage de communes appartenant à :
A16: CU ou métropoles(c) | B16: =B9/B$14 -> 0.003348554 | C16: =C9/C$14 -> 0.00932314 | D16: =D9/D$14 -> 0.014684133 | E16: =E9/E$14 -> 0.039811606 | F16: =F9/F$14 -> 0.08616188 | G16: =G9/G$14 -> 0.12550201 | H16: =H9/H$14 -> 0.21678892 | I16: =I9/I$14 -> 0.28571429 | ... O16: =O9/O$14 -> 0.046629455
A17: CA | B17: =B10/B$14 -> 0.068493151 | C17: =C10/C$14 -> 0.10180869 | D17: =D10/D$14 -> 0.16849778 | E17: =E10/E$14 -> 0.27246068 | F17: =F10/F$14 -> 0.35683203 | G17: =G10/G$14 -> 0.36746988 | H17: =H10/H$14 -> 0.38141809 | I17: =I10/I$14 -> 0.45207957 | ... O17: =O10/O$14 -> 0.21714613
A18: CC à FPU | B18: =B11/B$14 -> 0.67427702 | C18: =C11/C$14 -> 0.68431848 | D18: =D11/D$14 -> 0.66976548 | E18: =E11/E$14 -> 0.60268373 | F18: =F11/F$14 -> 0.50826806 | G18: =G11/G$14 -> 0.45883534 | H18: =H11/H$14 -> 0.36837816 | I18: =I11/I$14 -> 0.2477396 | ... K18: =K11/K$14 -> 0.010989011 | L18: - | M18: =M11/M$14 -> 0.62216714 | N18: =N11/N$14 -> 0.14040115 | O18: =O11/O$14 -> 0.60772864
A19: CC à FA | B19: =B12/B$14 -> 0.25388128 | C19: =C12/C$14 -> 0.20454969 | D19: =D12/D$14 -> 0.14684133 | E19: =E12/E$14 -> 0.084955123 | F19: =F12/F$14 -> 0.048738033 | G19: =G12/G$14 -> 0.048192771 | H19: =H12/H$14 -> 0.032599837 | I19: =I12/I$14 -> 0.014466546 | J19: - | K19: - | L19: - | M19: =M12/M$14 -> 0.13211166 | N19: =N12/N$14 -> 0.0076408787 | O19: =O12/O$14 -> 0.12838128
A20: non membre d'un groupement fiscalisé | B20: - | C20: - | D20: =D13/D$14 -> 0.00021128248 | E20: =E13/E$14 -> 8.8865192e-05 | F20: - | G20: - | H20: =H13/H$14 -> 0.00081499593 | I20: - | J20: - | K20: - | L20: - | M20: =M13/M$14 -> 0.00011803588 | N20: - | O20: =O13/O$14 -> 0.00011449835
A21: Total | B21: =B14/B$14 -> 1 | C21: =C14/C$14 -> 1 | D21: =D14/D$14 -> 1 | E21: =E14/E$14 -> 1 | F21: =F14/F$14 -> 1 | G21: =G14/G$14 -> 1 | H21: =H14/H$14 -> 1 | I21: =I14/I$14 -> 1 | ... O21: =O14/O$14 -> 1
A22: (a) Il s'agit, plus précisément, du nombre de budgets principaux de communes.
A23: (b) Il y a 1255 groupements à fiscalité propre au 01/01/2024 (y. c. la métropole de Lyon).
A24: (c) Y compris la métropole de Lyon.
A25: FA: Fiscalité Additionnelle ; FPU: Fiscalité Professionnelle Unique ;
A26: CU: Communauté Urbaine ; CA: Communauté d'Agglomération ;
A27: CC: Communauté de Communes.
A28: Lecture : il y a 11 communes de moins de 100 habitants appartenant à une CU ou à une métropole et ces communes représentent 0,3 % des communes de cette strate.
A29: Source : DGFIP, comptes de gestion, budgets principaux ; INSEE, Recensement de la population (population totale en 2024 - année de référence 2021) ; calculs DGCL.
A31: T 1.3.b - Répartition de la population des communes appartenant à un groupement à fiscalité propre selon le type de groupement en 2024
A32: Habitants comptés selon la population totale de l'Insee
B34: Moins | C34: De 100 | D34: De 200 | E34: De 500 | F34: De 2 000 | G34: De 3 500 | H34: De 5 000 | I34: De 10 000 | J34: De 20 000 | K34: De 50 000 | L34: 100000 | M34: Communes | N34: Communes | O34: Ensemble
A35: Strate des communes | B35: de 100 | C35: à moins de | D35: à moins de | E35: à moins de | F35: à moins de | G35: à moins de | H35: à moins de | I35: à moins de | J35: à moins de | K35: à moins de | L35: habitants | M35: de moins | N35: de 10 000 hab. | O35: des
B36: habitants | C36: 200 hab. | D36: 500 hab. | E36: 2 000 hab. | F36: 3 500 hab. | G36: 5 000 hab. | H36: 10 000 hab. | I36: 20 000 hab. | J36: 50 000 hab. | K36: 100 000 hab. | L36: et plus | M36: de 10 000 hab. | N36: et plus | O36: communes
A38: Nombre d'habitants appartenant à :
A39: CU ou métropoles(a) | B39: 857 | C39: 7302 | D39: 48416 | E39: 501787 | F39: 520479 | G39: 521567 | H39: 1895546 | I39: 2152524 | J39: 4776233 | K39: 3032672 | L39: 9560835 | M39: 3495954 | N39: 19522264 | O39: 23018218
A40: CA | B40: 14636 | C40: 82071 | D40: 540907 | E40: 3174205 | F40: 2158202 | G40: 1523844 | H40: 3249981 | I40: 3522107 | J40: 5972482 | K40: 3051518 | L40: 791736 | M40: 10743846 | N40: 13337843 | O40: 24081689
A41: CC à FPU | B41: 145526 | C41: 541295 | D41: 2054577 | E41: 6561600 | F41: 3050888 | G41: 1900346 | H41: 3111498 | I41: 1760804 | J41: 209986 | K41: 50537 | L41: - | M41: 17365730 | N41: 2021327 | O41: 19387057
A42: CC à FA | B42: 52089 | C42: 160287 | D42: 437616 | E42: 868783 | F42: 292270 | G42: 201238 | H42: 267391 | I42: 110265 | J42: - | K42: - | L42: - | M42: 2279674 | N42: 110265 | O42: 2389939
A43: non membre d'un groupement fiscalisé | B43: - | C43: - | D43: 687 | E43: 853 | F43: - | G43: - | H43: 5017 | I43: - | J43: - | K43: - | L43: - | M43: 6557 | N43: - | O43: 6557
A44: Total | B44: =SUM(B39:B43) -> 213108 | C44: =SUM(C39:C43) -> 790955 | D44: =SUM(D39:D43) -> 3082203 | E44: =SUM(E39:E43) -> 11107228 | F44: =SUM(F39:F43) -> 6021839 | G44: =SUM(G39:G43) -> 4146995 | H44: =SUM(H39:H43) -> 8529433 | I44: =SUM(I39:I43) -> 7545700 | ... O44: =SUM(O39:O43) -> 68883460
A45: Pourcentage d'habitants appartenant à :
A46: CU ou métropoles(a) | B46: =B39/B$44 -> 0.0040214351 | C46: =C39/C$44 -> 0.0092318779 | D46: =D39/D$44 -> 0.015708245 | E46: =E39/E$44 -> 0.045176618 | F46: =F39/F$44 -> 0.086431902 | G46: =G39/G$44 -> 0.12576986 | H46: =H39/H$44 -> 0.22223587 | I46: =I39/I$44 -> 0.28526499 | ... O46: =O39/O$44 -> 0.33416176
...

Sheet T 1.4
A1: T 1.4.a - Répartition des communes selon leur caractère touristique et de montagne en 2024
B4: Moins | C4: De 100 | D4: De 200 | E4: De 500 | F4: De 2 000 | G4: De 3 500 | H4: De 5 000 | I4: De 10 000 | J4: De 20 000 | K4: De 50 000 | L4: 100000 | M4: Communes | N4: Communes | O4: Ensemble
A5: Strate des communes | B5: de 100 | C5: à moins de | D5: à moins de | E5: à moins de | F5: à moins de | G5: à moins de | H5: à moins de | I5: à moins de | J5: à moins de | K5: à moins de | L5: habitants | M5: de moins | N5: de 10 000 hab. | O5: des
B6: habitants | C6: 200 hab. | D6: 500 hab. | E6: 2 000 hab. | F6: 3 500 hab. | G6: 5 000 hab. | H6: 10 000 hab. | I6: 20 000 hab. | J6: 50 000 hab. | K6: 100 000 hab. | L6: et plus | M6: de 10 000 hab. | N6: et plus | O6: communes
A7: En nombre de communes(a)
A8: Communes touristiques(b) :
A9: - Communes touristiques du littoral maritime | B9: 3 | C9: 18 | D9: 33 | E9: 160 | F9: 116 | G9: 74 | H9: 71 | I9: 37 | J9: 17 | K9: 3 | L9: - | M9: 475 | N9: 57 | O9: 532
A10: - Communes touristiques "supports de station de sport d'hiver" | B10: 10 | C10: 21 | D10: 77 | E10: 139 | F10: 27 | G10: 14 | H10: 7 | I10: 4 | J10: - | K10: - | L10: - | M10: 295 | N10: 4 | O10: 299
A11: - Autres communes touristiques de montagne | B11: 145 | C11: 141 | D11: 232 | E11: 258 | F11: 51 | G11: 17 | H11: 10 | I11: 1 | J11: 1 | K11: - | L11: - | M11: 854 | N11: 2 | O11: 856
A12: - Autres communes touristiques | B12: 6 | C12: 23 | D12: 66 | E12: 194 | F12: 72 | G12: 29 | H12: 32 | I12: 12 | J12: 3 | K12: - | L12: - | M12: 422 | N12: 15 | O12: 437
A13: Nombre total des communes touristiques(b) | B13: =SUM(B9:B12) -> 164 | C13: =SUM(C9:C12) -> 203 | D13: =SUM(D9:D12) -> 408 | E13: =SUM(E9:E12) -> 751 | F13: =SUM(F9:F12) -> 266 | G13: =SUM(G9:G12) -> 134 | H13: =SUM(H9:H12) -> 120 | I13: =SUM(I9:I12) -> 54 | ... K13: =SUM(K9:K12) -> 3 | L13: - | M13: =SUM(M9:M12) -> 2046 | N13: =SUM(N9:N12) -> 78 | O13: =SUM(O9:O12) -> 2124
A14: Communes non touristiques :
A15: - Communes de montagne | B15: 889 | C15: 963 | D15: 1332 | E15: 1222 | F15: 169 | G15: 69 | H15: 107 | I15: 44 | J15: 18 | K15: 6 | L15: 4 | M15: 4751 | N15: 72 | O15: 4823
A16: - Communes hors montagne | B16: 2232 | C16: 4197 | D16: 7726 | E16: 9280 | F16: 1863 | G16: 793 | H16: 1000 | I16: 455 | J16: 322 | K16: 82 | L16: 38 | M16: 27091 | N16: 897 | O16: 27988
A17: Nombre total des communes non touristiques | B17: =SUM(B15:B16) -> 3121 | C17: =SUM(C15:C16) -> 5160 | D17: =SUM(D15:D16) -> 9058 | E17: =SUM(E15:E16) -> 10502 | F17: =SUM(F15:F16) -> 2032 | G17: =SUM(G15:G16) -> 862 | H17: =SUM(H15:H16) -> 1107 | I17: =SUM(I15:I16) -> 499 | ... O17: =SUM(O15:O16) -> 32811
A18: Part des communes touristiques(b) appartenant à :
A19: - Communes touristiques du littoral maritime | B19: =B9/B$13 -> 0.018292683 | C19: =C9/C$13 -> 0.088669951 | D19: =D9/D$13 -> 0.080882353 | E19: =E9/E$13 -> 0.21304927 | F19: =F9/F$13 -> 0.43609023 | G19: =G9/G$13 -> 0.55223881 | H19: =H9/H$13 -> 0.59166667 | I19: =I9/I$13 -> 0.68518519 | ... K19: =K9/K$13 -> 1 | L19: - | M19: =M9/M$13 -> 0.23216031 | N19: =N9/N$13 -> 0.73076923 | O19: =O9/O$13 -> 0.25047081
A20: - Communes touristiques "supports de station de sport d'hiver" | B20: =B10/B$13 -> 0.06097561 | C20: =C10/C$13 -> 0.10344828 | D20: =D10/D$13 -> 0.18872549 | E20: =E10/E$13 -> 0.18508655 | F20: =F10/F$13 -> 0.10150376 | G20: =G10/G$13 -> 0.10447761 | H20: =H10/H$13 -> 0.058333333 | I20: =I10/I$13 -> 0.074074074 | J20: - | K20: - | L20: - | M20: =M10/M$13 -> 0.14418377 | N20: =N10/N$13 -> 0.051282051 | O20: =O10/O$13 -> 0.14077213
A21: - Autres communes touristiques de montagne | B21: =B11/B$13 -> 0.88414634 | C21: =C11/C$13 -> 0.69458128 | D21: =D11/D$13 -> 0.56862745 | E21: =E11/E$13 -> 0.34354194 | F21: =F11/F$13 -> 0.19172932 | G21: =G11/G$13 -> 0.12686567 | H21: =H11/H$13 -> 0.083333333 | I21: =I11/I$13 -> 0.018518519 | J21: =J11/J$13 -> 0.047619048 | K21: - | L21: - | M21: =M11/M$13 -> 0.4173998 | N21: =N11/N$13 -> 0.025641026 | O21: =O11/O$13 -> 0.40301318
A22: - Autres communes touristiques | B22: =B12/B$13 -> 0.036585366 | C22: =C12/C$13 -> 0.11330049 | D22: =D12/D$13 -> 0.16176471 | E22: =E12/E$13 -> 0.25832224 | F22: =F12/F$13 -> 0.27067669 | G22: =G12/G$13 -> 0.21641791 | H22: =H12/H$13 -> 0.26666667 | I22: =I12/I$13 -> 0.22222222 | J22: =J12/J$13 -> 0.14285714 | K22: - | L22: - | M22: =M12/M$13 -> 0.20625611 | N22: =N12/N$13 -> 0.19230769 | O22: =O12/O$13 -> 0.20574388
A23: Ensemble des communes touristiques(b) | B23: =B13/B$13 -> 1 | C23: =C13/C$13 -> 1 | D23: =D13/D$13 -> 1 | E23: =E13/E$13 -> 1 | F23: =F13/F$13 -> 1 | G23: =G13/G$13 -> 1 | H23: =H13/H$13 -> 1 | I23: =I13/I$13 -> 1 | ... K23: =K13/K$13 -> 1 | L23: - | M23: =M13/M$13 -> 1 | N23: =N13/N$13 -> 1 | O23: =O13/O$13 -> 1
A24: Part des communes non touristiques appartenant à :
A25: - Communes de montagne | B25: =B15/B$17 -> 0.2848446 | C25: =C15/C$17 -> 0.18662791 | D25: =D15/D$17 -> 0.14705233 | E25: =E15/E$17 -> 0.11635879 | F25: =F15/F$17 -> 0.083169291 | G25: =G15/G$17 -> 0.080046404 | H25: =H15/H$17 -> 0.096657633 | I25: =I15/I$17 -> 0.088176353 | ... O25: =O15/O$17 -> 0.14699339
A26: - Communes hors montagne | B26: =B16/B$17 -> 0.7151554 | C26: =C16/C$17 -> 0.81337209 | D26: =D16/D$17 -> 0.85294767 | E26: =E16/E$17 -> 0.88364121 | F26: =F16/F$17 -> 0.91683071 | G26: =G16/G$17 -> 0.9199536 | H26: =H16/H$17 -> 0.90334237 | I26: =I16/I$17 -> 0.91182365 | ... O26: =O16/O$17 -> 0.85300661
A27: Ensemble des communes non touristiques | B27: =B17/B$17 -> 1 | C27: =C17/C$17 -> 1 | D27: =D17/D$17 -> 1 | E27: =E17/E$17 -> 1 | F27: =F17/F$17 -> 1 | G27: =G17/G$17 -> 1 | H27: =H17/H$17 -> 1 | I27: =I17/I$17 -> 1 | ... O27: =O17/O$17 -> 1
A28: (a) Il s'agit, plus précisément, du nombre de budgets principaux de communes.
A29: (b) Les communes touristiques concernent uniquement la France métropolitaine.
A30: Lecture : il y a seulement trois communes touristiques du littoral maritime de moins de 100 habitants. Elle correspond à 1,8 % de l'ensemble des communes touristiques de moins de 100 habitants.
A31: Source : DGFIP, comptes de gestion ; INSEE, Recensement de la population (population totale en 2024 - année de référence 2021) ; calculs DGCL. ; calculs DGCL.
A33: T 1.4.b - Répartition de la «population DGF» des communes selon leur caractère touristique et de montagne en 2024
B36: Moins | C36: De 100 | D36: De 200 | E36: De 500 | F36: De 2 000 | G36: De 3 500 | H36: De 5 000 | I36: De 10 000 | J36: De 20 000 | K36: De 50 000 | L36: 100000 | M36: Communes | N36: Communes | O36: Ensemble
A37: Strate des communes(a) | B37: de 100 | C37: à moins de | D37: à moins de | E37: à moins de | F37: à moins de | G37: à moins de | H37: à moins de | I37: à moins de | J37: à moins de | K37: à moins de | L37: habitants | M37: de moins | N37: de 10 000 hab. | O37: des
B38: habitants | C38: 200 hab. | D38: 500 hab. | E38: 2 000 hab. | F38: 3 500 hab. | G38: 5 000 hab. | H38: 10 000 hab. | I38: 20 000 hab. | J38: 50 000 hab. | K38: 100 000 hab. | L38: et plus | M38: de 10 000 hab. | N38: et plus | O38: communes
A40: Nombre d'habitants «DGF» des communes touristiques(b) :
A41: - Communes touristiques du littoral maritime | B41: 466 | C41: 6063 | D41: 18917 | E41: 322405 | F41: 477537 | G41: 503400 | H41: 750217 | I41: 709482 | J41: 719743 | K41: 239732 | L41: - | M41: 2079005 | N41: 1668957 | O41: 3747962
A42: - Communes touristiques "supports de station de sport d'hiver" | B42: 2261 | C42: 11791 | D42: 72572 | E42: 334525 | F42: 131352 | G42: 94591 | H42: 81819 | I42: 56358 | J42: - | K42: - | L42: - | M42: 728911 | N42: 56358 | O42: 785269
A43: - Autres communes touristiques de montagne | B43: 15497 | C43: 33841 | D43: 109980 | E43: 302490 | F43: 145325 | G43: 79307 | H43: 67262 | I43: 14934 | J43: 23545 | K43: - | L43: - | M43: 753702 | N43: 38479 | O43: 792181
A44: - Autres communes touristiques | B44: 537 | C44: 5122 | D44: 29518 | E44: 242182 | F44: 214716 | G44: 127250 | H44: 245562 | I44: 168340 | J44: 74549 | K44: - | L44: - | M44: 864887 | N44: 242889 | O44: 1107776
A45: Nombre total d'habitants «DGF» des communes touristiques(b) | B45: =SUM(B41:B44) -> 18761 | C45: =SUM(C41:C44) -> 56817 | D45: =SUM(D41:D44) -> 230987 | E45: =SUM(E41:E44) -> 1201602 | F45: =SUM(F41:F44) -> 968930 | G45: =SUM(G41:G44) -> 804548 | H45: =SUM(H41:H44) -> 1144860 | I45: =SUM(I41:I44) -> 949114 | ... K45: =SUM(K41:K44) -> 239732 | L45: - | M45: =SUM(M41:M44) -> 4426505 | N45: =SUM(N41:N44) -> 2006683 | O45: =SUM(O41:O44) -> 6433188
A46: Nombre d'habitants «DGF» des communes non touristiques :
...

Sheet T 1.5
A1: T 1.5.a - Répartition des communes selon leur caractère urbain ou rural en 2024
B4: Moins | C4: De 100 | D4: De 200 | E4: De 500 | F4: De 2 000 | G4: De 3 500 | H4: De 5 000 | I4: De 10 000 | J4: De 20 000 | K4: De 50 000 | L4: 100000 | M4: Budgets des | N4: Budgets des | O4: Ensemble
A5: Strate des communes | B5: de 100 | C5: à moins de | D5: à moins de | E5: à moins de | F5: à moins de | G5: à moins de | H5: à moins de | I5: à moins de | J5: à moins de | K5: à moins de | L5: habitants | M5: communes de moins | N5: communes de | O5: des
B6: habitants | C6: 200 hab. | D6: 500 hab. | E6: 2 000 hab. | F6: 3 500 hab. | G6: 5 000 hab. | H6: 10 000 hab. | I6: 20 000 hab. | J6: 50 000 hab. | K6: 100 000 hab. | L6: et plus | M6: de 10 000 hab. | N6: 10 000 hab. et plus | O6: budgets
A7: En nombre de communes (a)
A8: Budgets des communes appartenant à :
A9: Communes rurales | B9: 3285 | C9: 5361 | D9: 9405 | E9: 10245 | F9: 1565 | G9: 560 | H9: 302 | I9: 16 | J9: 4 | K9: - | L9: - | M9: 30723 | N9: 20 | O9: 30743
A10: Communes urbaines | B10: - | C10: 2 | D10: 61 | E10: 1008 | F10: 733 | G10: 436 | H10: 925 | I10: 537 | J10: 357 | K10: 91 | L10: 42 | M10: 3165 | N10: 1027 | O10: 4192
A11: Total des communes rurales et urbaines | B11: =SUM(B9:B10) -> 3285 | C11: =SUM(C9:C10) -> 5363 | D11: =SUM(D9:D10) -> 9466 | E11: =SUM(E9:E10) -> 11253 | F11: =SUM(F9:F10) -> 2298 | G11: =SUM(G9:G10) -> 996 | H11: =SUM(H9:H10) -> 1227 | I11: =SUM(I9:I10) -> 553 | ... O11: =SUM(O9:O10) -> 34935
A12: Type de communes rurales et urbaines :
A13: Grands centres urbains | B13: - | C13: - | D13: - | E13: 10 | F13: 32 | G13: 45 | H13: 166 | I13: 191 | J13: 215 | K13: 73 | L13: 41 | M13: 253 | N13: 520 | O13: 773
A14: Centres urbains intermédiaires | B14: - | C14: - | D14: - | E14: 8 | F14: 20 | G14: 23 | H14: 135 | I14: 225 | J14: 115 | K14: 18 | L14: 1 | M14: 186 | N14: 359 | O14: 545
A15: Petites villes | B15: - | C15: 2 | D15: 26 | E15: 263 | F15: 157 | G15: 108 | H15: 273 | I15: 63 | J15: 9 | K15: - | L15: - | M15: 829 | N15: 72 | O15: 901
A16: Ceintures urbaines | B16: - | C16: - | D16: 35 | E16: 727 | F16: 524 | G16: 260 | H16: 351 | I16: 58 | J16: 18 | K16: - | L16: - | M16: 1897 | N16: 76 | O16: 1973
A17: Bourgs ruraux | B17: 2 | C17: 11 | D17: 154 | E17: 3035 | F17: 1161 | G17: 468 | H17: 256 | I17: 13 | J17: 4 | K17: - | L17: - | M17: 5087 | N17: 17 | O17: 5104
A18: Rural à habitat dispersé | B18: 1093 | C18: 3243 | D18: 6949 | E18: 6577 | F18: 382 | G18: 90 | H18: 43 | I18: 3 | J18: - | K18: - | L18: - | M18: 18377 | N18: 3 | O18: 18380
A19: Rural à habitat très dispersé | B19: 2190 | C19: 2107 | D19: 2302 | E19: 632 | F19: 22 | G19: 2 | H19: 3 | I19: - | J19: - | K19: - | L19: - | M19: 7258 | N19: - | O19: 7258
A20: Ensemble des communes rurales et urbaines | B20: =SUM(B13:B19) -> 3285 | C20: =SUM(C13:C19) -> 5363 | D20: =SUM(D13:D19) -> 9466 | E20: =SUM(E13:E19) -> 11252 | F20: =SUM(F13:F19) -> 2298 | G20: =SUM(G13:G19) -> 996 | H20: =SUM(H13:H19) -> 1227 | I20: =SUM(I13:I19) -> 553 | ... O20: =SUM(O13:O19) -> 34934
A21: Proportion des communes appartenant à :
A22: Communes rurales | B22: =B9/B$11 -> 1 | C22: =C9/C$11 -> 0.99962707 | D22: =D9/D$11 -> 0.99355588 | E22: =E9/E$11 -> 0.91042389 | F22: =F9/F$11 -> 0.68102698 | G22: =G9/G$11 -> 0.562249 | H22: =H9/H$11 -> 0.24612877 | I22: =I9/I$11 -> 0.028933092 | J22: =J9/J$11 -> 0.011080332 | K22: - | L22: - | M22: =M9/M$11 -> 0.90660411 | N22: =N9/N$11 -> 0.019102197 | O22: =O9/O$11 -> 0.88000572
A23: Communes urbaines | B23: - | C23: - | D23: =D10/D$11 -> 0.0064441158 | E23: =E10/E$11 -> 0.089576113 | F23: =F10/F$11 -> 0.31897302 | G23: =G10/G$11 -> 0.437751 | H23: =H10/H$11 -> 0.75387123 | I23: =I10/I$11 -> 0.97106691 | J23: =J10/J$11 -> 0.98891967 | K23: =K10/K$11 -> 1 | ... O23: =O10/O$11 -> 0.11999428
A24: Ensemble des communes rurales et urbaines | B24: =B11/B$11 -> 1 | C24: =C11/C$11 -> 1 | D24: =D11/D$11 -> 1 | E24: =E11/E$11 -> 1 | F24: =F11/F$11 -> 1 | G24: =G11/G$11 -> 1 | H24: =H11/H$11 -> 1 | I24: =I11/I$11 -> 1 | ... O24: =O11/O$11 -> 1
A25: Type de communes rurales et urbaines :
A26: Grands centres urbains | B26: - | C26: - | D26: - | E26: =E13/E$20 -> 0.00088873089 | F26: =F13/F$20 -> 0.013925152 | G26: =G13/G$20 -> 0.045180723 | H26: =H13/H$20 -> 0.13528932 | I26: =I13/I$20 -> 0.34538879 | J26: =J13/J$20 -> 0.59556787 | K26: =K13/K$20 -> 0.8021978 | L26: =L13/L$20 -> 0.97619048 | ... O26: =O13/O$20 -> 0.02212744
A27: Centres urbains intermédiaires | B27: - | C27: - | D27: - | E27: =E14/E$20 -> 0.00071098471 | F27: =F14/F$20 -> 0.0087032202 | G27: =G14/G$20 -> 0.023092369 | H27: =H14/H$20 -> 0.11002445 | I27: =I14/I$20 -> 0.40687161 | J27: =J14/J$20 -> 0.31855956 | K27: =K14/K$20 -> 0.1978022 | L27: =L14/L$20 -> 0.023809524 | ... O27: =O14/O$20 -> 0.015600847
A28: Petites villes | B28: - | C28: =C15/C$20 -> 0.0003729256 | D28: =D15/D$20 -> 0.0027466723 | E28: =E15/E$20 -> 0.023373622 | F28: =F15/F$20 -> 0.068320279 | G28: =G15/G$20 -> 0.10843373 | H28: =H15/H$20 -> 0.22249389 | I28: =I15/I$20 -> 0.11392405 | J28: =J15/J$20 -> 0.024930748 | K28: - | L28: - | M28: =M15/M$20 -> 0.024463659 | N28: =N15/N$20 -> 0.068767908 | O28: =O15/O$20 -> 0.025791493
A29: Ceintures urbaines | B29: - | C29: - | D29: =D16/D$20 -> 0.0036974435 | E29: =E16/E$20 -> 0.064610736 | F29: =F16/F$20 -> 0.22802437 | G29: =G16/G$20 -> 0.26104418 | H29: =H16/H$20 -> 0.28606357 | I29: =I16/I$20 -> 0.10488246 | J29: =J16/J$20 -> 0.049861496 | K29: - | L29: - | M29: =M16/M$20 -> 0.055980169 | N29: =N16/N$20 -> 0.072588348 | O29: =O16/O$20 -> 0.05647793
A30: Bourgs ruraux | B30: =B17/B$20 -> 0.00060882801 | C30: =C17/C$20 -> 0.0020510908 | D30: =D17/D$20 -> 0.016268751 | E30: =E17/E$20 -> 0.26972983 | F30: =F17/F$20 -> 0.50522193 | G30: =G17/G$20 -> 0.46987952 | H30: =H17/H$20 -> 0.20863896 | I30: =I17/I$20 -> 0.023508137 | J30: =J17/J$20 -> 0.011080332 | K30: - | L30: - | M30: =M17/M$20 -> 0.15011656 | N30: =N17/N$20 -> 0.016236867 | O30: =O17/O$20 -> 0.14610408
A31: Rural à habitat dispersé | B31: =B18/B$20 -> 0.33272451 | C31: =C18/C$20 -> 0.60469886 | D31: =D18/D$20 -> 0.73410099 | E31: =E18/E$20 -> 0.58451831 | F31: =F18/F$20 -> 0.16623151 | G31: =G18/G$20 -> 0.090361446 | H31: =H18/H$20 -> 0.035044825 | I31: =I18/I$20 -> 0.0054249548 | J31: - | K31: - | L31: - | M31: =M18/M$20 -> 0.54230236 | N31: =N18/N$20 -> 0.0028653295 | O31: =O18/O$20 -> 0.526135
A32: Rural à habitat très dispersé | B32: =B19/B$20 -> 0.66666667 | C32: =C19/C$20 -> 0.39287712 | D32: =D19/D$20 -> 0.24318614 | E32: =E19/E$20 -> 0.056167792 | F32: =F19/F$20 -> 0.0095735422 | G32: =G19/G$20 -> 0.0020080321 | H32: =H19/H$20 -> 0.0024449878 | I32: - | J32: - | K32: - | L32: - | M32: =M19/M$20 -> 0.21418243 | N32: - | O32: =O19/O$20 -> 0.20776321
A33: Ensemble des communes rurales et urbaines | B33: =B20/B$20 -> 1 | C33: =C20/C$20 -> 1 | D33: =D20/D$20 -> 1 | E33: =E20/E$20 -> 1 | F33: =F20/F$20 -> 1 | G33: =G20/G$20 -> 1 | H33: =H20/H$20 -> 1 | I33: =I20/I$20 -> 1 | ... O33: =O20/O$20 -> 1
A34: (a) Il s'agit, plus précisément, du nombre de budgets principaux de communes.
A35: Lecture : il y a 3 285 communes rurales de moins de 100 habitants qui constituent 100,0 % des communes de cette strate.
A36: Source : DGFIP, comptes de gestion, budgets principaux. INSEE, Recensement de la population (population totale en 2024 - année de référence 2021) ; calculs DGCL. Grille de densité de l'Insee au 1er janvier 2024 définissant le rural.
A38: T 1.5.b - Répartition de la population totale des communes selon leur caractère urbain ou rural en 2024
B41: Moins | C41: De 100 | D41: De 200 | E41: De 500 | F41: De 2 000 | G41: De 3 500 | H41: De 5 000 | I41: De 10 000 | J41: De 20 000 | K41: De 50 000 | L41: 100000 | M41: Communes | N41: Communes | O41: Ensemble
A42: Strate des communes | B42: de 100 | C42: à moins de | D42: à moins de | E42: à moins de | F42: à moins de | G42: à moins de | H42: à moins de | I42: à moins de | J42: à moins de | K42: à moins de | L42: habitants | M42: de moins | N42: de 10 000 hab. | O42: des
B43: habitants | C43: 200 hab. | D43: 500 hab. | E43: 2 000 hab. | F43: 3 500 hab. | G43: 5 000 hab. | H43: 10 000 hab. | I43: 20 000 hab. | J43: 50 000 hab. | K43: 100 000 hab. | L43: et plus | M43: de 10 000 hab. | N43: et plus | O43: communes
A44: En nombre d'habitants
A45: Nombre d'habitants des communes appartenant à :
...

Sheet T 2.1
A1: T 2.1.a - Comptes des communes par strate de population en 2024
O2: En millions d'euros
A3: Exercice 2024 | B3: Moins | C3: De 100 | D3: De 200 | E3: De 500 | F3: De 2 000 | G3: De 3 500 | H3: De 5 000 | I3: De 10 000 | J3: De 20 000 | K3: De 50 000 | L3: 100000 | M3: Communes | N3: Communes | O3: Ensemble
A4: Opérations réelles | B4: de 100 | C4: à moins de | D4: à moins de | E4: à moins de | F4: à moins de | G4: à moins de | H4: à moins de | I4: à moins de | J4: à moins de | K4: à moins de | L4: habitants | M4: de moins | N4: de 10 000 hab. | O4: des
A5: Hors gestion active de la dette | B5: habitants | C5: 200 hab. | D5: 500 hab. | E5: 2 000 hab. | F5: 3 500 hab. | G5: 5 000 hab. | H5: 10 000 hab. | I5: 20 000 hab. | J5: 50 000 hab. | K5: 100 000 hab. | L5: et plus | M5: de 10 000 hab. | N5: et plus | O5: communes
A7: DÉPENSES DE FONCTIONNEMENT (1) | B7: 236.14415 | C7: 657.05893 | D7: 2230.9703 | E7: 8411.4372 | F7: 5268.2178 | G7: 4143.8454 | H7: 9454.0355 | I7: 9446.0116 | J7: 15316.956 | K7: 9242.6118 | L7: 18394.633 | M7: 30401.709 | N7: 52400.213 | O7: 82801.922
A8: Achats et charges externes | B8: 95.217149 | C8: 253.84986 | D8: 809.33058 | E8: 2912.2829 | F8: 1750.3841 | G8: 1290.4513 | H8: 2710.278 | I8: 2465.7321 | J8: 3800.826 | K8: 2098.2897 | L8: 3394.4908 | M8: 9821.7939 | N8: 11759.339 | O8: 21581.133
A9: Frais de personnel | B9: 53.954731 | C9: 183.70054 | D9: 777.62825 | E9: 3725.8857 | F9: 2664.1262 | G9: 2224.9285 | H9: 5375.3304 | I9: 5610.6607 | J9: 9307.8862 | K9: 5582.0481 | L9: 9156.2487 | M9: 15005.554 | N9: 29656.844 | O9: 44662.398
A10: Charges financières | B10: 3.4415664 | C10: 10.967835 | D10: 38.639138 | E10: 161.93275 | F10: 102.66174 | G10: 75.225389 | H10: 171.04714 | I10: 163.33077 | J10: 301.3237 | K10: 240.00432 | L10: 447.12192 | M10: 563.91557 | N10: 1151.7807 | O10: 1715.6963
A11: Dépenses d'intervention | B11: 29.52835 | C11: 91.1942 | D11: 342.0985 | E11: 901.31633 | F11: 466.33267 | G11: 365.32943 | H11: 874.18558 | I11: 942.09891 | J11: 1538.2989 | K11: 1074.4666 | L11: 4963.1689 | M11: 3069.9851 | N11: 8518.0333 | O11: 11588.018
A12: Autres dépenses de fonctionnement | B12: 54.002351 | C12: 117.34649 | D12: 263.27382 | E12: 710.01948 | F12: 284.71313 | G12: 187.91079 | H12: 323.19432 | I12: 264.18904 | J12: 368.62129 | K12: 247.80304 | L12: 433.60314 | M12: 1940.4604 | N12: 1314.2165 | O12: 3254.6769
A13: RECETTES DE FONCTIONNEMENT (2) | B13: 327.33664 | C13: 879.40834 | D13: 2876.9452 | E13: 10524.91 | F13: 6502.965 | G13: 5057.2184 | H13: 11267.436 | I13: 10972.136 | J13: 17591.779 | K13: 10685.609 | L13: 20325.466 | M13: 37436.22 | N13: 59574.99 | O13: 97011.209
A14: Impôts et taxes | B14: 139.84497 | C14: 406.35498 | D14: 1463.9781 | E14: 6048.5737 | F14: 4077.9159 | G14: 3287.0285 | H14: 7537.5227 | I14: 7453.0177 | J14: 12106.778 | K14: 7342.6629 | L14: 14740.481 | M14: 22961.219 | N14: 41642.939 | O14: 64604.158
A15: - Impôts locaux | B15: 96.505899 | C15: 312.26567 | D15: 1210.9477 | E15: 5351.1737 | F15: 3676.6251 | G15: 2922.2429 | H15: 6653.7597 | I15: 6566.59 | J15: 10998.451 | K15: 6532.6312 | L15: 10477.738 | M15: 20223.521 | N15: 34575.41 | O15: 54798.931
A16: (dont : fiscalité reversée) | B16: 15.667474 | C16: 38.275645 | D16: 142.92086 | E16: 865.34718 | F16: 690.43938 | G16: 582.49506 | H16: 1410.796 | I16: 1456.8664 | J16: 2230.5912 | K16: 1474.5025 | L16: 2032.1082 | M16: 3745.9416 | N16: 7194.0683 | O16: 10940.01
A17: - Autres impôts et taxes | B17: 43.339069 | C17: 94.089303 | D17: 253.03041 | E17: 697.40005 | F17: 401.29086 | G17: 364.78559 | H17: 883.76301 | I17: 886.4277 | J17: 1108.3268 | K17: 810.03173 | L17: 4262.7424 | M17: 2737.6983 | N17: 7067.5286 | O17: 9805.2269
A18: Concours de l'État | B18: 109.89019 | C18: 267.36099 | D18: 795.64879 | E18: 2507.7392 | F18: 1309.7665 | G18: 923.54249 | H18: 1918.4624 | I18: 1810.5485 | J18: 2743.5581 | K18: 1676.9876 | L18: 2168.5447 | M18: 7832.4106 | N18: 8399.639 | O18: 16232.05
... A44: Dette au 31 décembre (12) | B44: 137.78751 | C44: 460.62662 | D44: 1564.9891 | E44: 6342.5843 | F44: 3924.3565 | G44: 2989.5653 | H44: 6507.3161 | I44: 6068.3689 | J44: 10808.237 | K44: 8112.9677 | L44: 19615.128 | M44: 21927.225 | N44: 44604.702 | O44: 66531.928
A45: Ratios
A46: Taux d'épargne brute = (3) / (2) | B46: 0.27858932 | C46: 0.25283978 | D46: 0.224535 | E46: 0.20080673 | F46: 0.1898745 | G46: 0.18060779 | H46: 0.16094173 | I46: 0.13909091 | J46: 0.1293117 | K46: 0.13504117 | L46: 0.094995741 | M46: 0.18790654 | N46: 0.1204327 | O46: 0.14647057
A47: Taux d'épargne nette = [(3)-(8)] / (2) | B47: 0.19914299 | C47: 0.16730207 | D47: 0.14113036 | E47: 0.12064206 | F47: 0.12104443 | G47: 0.11762612 | H47: 0.097989305 | I47: 0.08101283 | J47: 0.066003645 | K47: 0.058143412 | L47: 0.035164821 | M47: 0.11684357 | N47: 0.056836677 | O47: 0.079993087
A48: Taux d'endettement = (12) / (2) | B48: 0.42093518 | C48: 0.52379151 | D48: 0.543976 | E48: 0.60262599 | F48: 0.60347187 | G48: 0.59114816 | H48: 0.57753299 | I48: 0.55307088 | J48: 0.61439138 | K48: 0.75924243 | L48: 0.96505183 | M48: 0.58572221 | N48: 0.74871523 | O48: 0.68581691
A49: Délai de désendettement = (12) / (3) | B49: 1.5109523 | C49: 2.0716341 | D49: 2.422678 | E49: 3.0010249 | F49: 3.1782671 | G49: 3.2731044 | H49: 3.5884603 | I49: 3.9763264 | J49: 4.7512436 | K49: 5.6223035 | L49: 10.158896 | M49: 3.1170933 | N49: 6.2168764 | O49: 4.6822846
A50: R7 : Dépenses de personnel / dépenses réelles de fonctionnement (DRF) | B50: 0.22848219 | C50: 0.27958001 | D50: 0.34856056 | E50: 0.44295471 | F50: 0.5056978 | G50: 0.53692363 | H50: 0.56857523 | I50: 0.5939714 | J50: 0.60768511 | K50: 0.60394705 | L50: 0.49776739 | M50: 0.49357601 | N50: 0.565968 | O50: 0.53938842
A51: R9 : Marge d'autofinancement courant (MAC)=(DRF+Remboursement de dette) / RRF | B51: 0.80035742 | C51: 0.83239488 | D51: 0.85831564 | E51: 0.87831883 | F51: 0.87679475 | G51: 0.87913537 | H51: 0.898259 | I51: 0.91597124 | J51: 0.93185245 | K51: 0.94033988 | L51: 0.96396023 | M51: 0.88086822 | N51: 0.94140425 | O51: 0.91804365
A52: R10 : Dépenses d'équipement brutes (a) / RRF (Taux d'équipement) | B52: 0.46193054 | C52: 0.44625725 | D52: 0.41192113 | E52: 0.39868697 | F52: 0.3754264 | G52: 0.345373 | H52: 0.31807931 | I52: 0.26707508 | J52: 0.2507679 | K52: 0.25324962 | L52: 0.19474769 | M52: 0.36587075 | N52: 0.23510372 | O52: 0.28556617
A53: (a) C'est-à-dire y compris les travaux en régie, les travaux effectués d'office pour le compte de tiers, les opérations di'nvestissement sur établissements d'enseignement et les opérations sous mandat.
A54: Champ : France entière (France métropolitaine et DOM).
A55: Lecture : Les dépenses de fonctionnement des communes de moins de 100 habitants se montent à 236 M€.
A56: Source : DGFiP-Comptes de gestion ; budgets principaux - opérations réelles. Calculs DGCL. Montants calculés hors gestion active de la dette. INSEE, Recensement de la population (population totale en 2024 - année de référence 2021)
A58: T 2.1.b - Structure des dépenses et recettes des communes par strate de population en 2024
O59: En %
A60: Exercice 2024 | B60: Moins | C60: De 100 | D60: De 200 | E60: De 500 | F60: De 2 000 | G60: De 3 500 | H60: De 5 000 | I60: De 10 000 | J60: De 20 000 | K60: De 50 000 | L60: 100000 | M60: Communes | N60: Communes | O60: Ensemble
A61: Opérations réelles | B61: de 100 | C61: à moins de | D61: à moins de | E61: à moins de | F61: à moins de | G61: à moins de | H61: à moins de | I61: à moins de | J61: à moins de | K61: à moins de | L61: habitants | M61: de moins | N61: de 10 000 hab. | O61: des
A62: Hors gestion active de la dette | B62: habitants | C62: 200 hab. | D62: 500 hab. | E62: 2 000 hab. | F62: 3 500 hab. | G62: 5 000 hab. | H62: 10 000 hab. | I62: 20 000 hab. | J62: 50 000 hab. | K62: 100 000 hab. | L62: et plus | M62: de 10 000 hab. | N62: et plus | O62: communes
A63: Structure de fonctionnement
A64: DÉPENSES DE FONCTIONNEMENT (1) | B64: =B7/B$7 -> 1 | C64: =C7/C$7 -> 1 | D64: =D7/D$7 -> 1 | E64: =E7/E$7 -> 1 | F64: =F7/F$7 -> 1 | G64: =G7/G$7 -> 1 | H64: =H7/H$7 -> 1 | I64: =I7/I$7 -> 1 | ... O64: =O7/O$7 -> 1
A65: Achats et charges externes | B65: =B8/B$7 -> 0.40321621 | C65: =C8/C$7 -> 0.38634261 | D65: =D8/D$7 -> 0.36277067 | E65: =E8/E$7 -> 0.34622894 | F65: =F8/F$7 -> 0.33225356 | G65: =G8/G$7 -> 0.31141395 | H65: =H8/H$7 -> 0.28667948 | I65: =I8/I$7 -> 0.26103421 | ... O65: =O8/O$7 -> 0.26063565
A66: Frais de personnel | B66: =B9/B$7 -> 0.22848219 | C66: =C9/C$7 -> 0.27958001 | D66: =D9/D$7 -> 0.34856056 | E66: =E9/E$7 -> 0.4429547 | F66: =F9/F$7 -> 0.5056978 | G66: =G9/G$7 -> 0.53692363 | H66: =H9/H$7 -> 0.56857523 | I66: =I9/I$7 -> 0.5939714 | ... O66: =O9/O$7 -> 0.53938842
A67: Charges financières | B67: =B10/B$7 -> 0.014574007 | C67: =C10/C$7 -> 0.016692316 | D67: =D10/D$7 -> 0.017319432 | E67: =E10/E$7 -> 0.019251497 | F67: =F10/F$7 -> 0.019486996 | G67: =G10/G$7 -> 0.018153522 | H67: =H10/H$7 -> 0.018092501 | I67: =I10/I$7 -> 0.017290978 | ... O67: =O10/O$7 -> 0.020720489
...

Sheet T 2.2
A1: T 2.2 - Dépenses et recettes par habitant (a) des communes en 2024
O2: En €/habitant
A3: Exercice 2024 | B3: Moins | C3: De 100 | D3: De 200 | E3: De 500 | F3: De 2 000 | G3: De 3 500 | H3: De 5 000 | I3: De 10 000 | J3: De 20 000 | K3: De 50 000 | L3: 100000 | M3: Communes | N3: Communes | O3: Ensemble
A4: Opérations réelles | B4: de 100 | C4: à moins de | D4: à moins de | E4: à moins de | F4: à moins de | G4: à moins de | H4: à moins de | I4: à moins de | J4: à moins de | K4: à moins de | L4: habitants | M4: de moins | N4: de 10 000 hab. | O4: des
A5: Hors gestion active de la dette | B5: habitants | C5: 200 hab. | D5: 500 hab. | E5: 2 000 hab. | F5: 3 500 hab. | G5: 5 000 hab. | H5: 10 000 hab. | I5: 20 000 hab. | J5: 50 000 hab. | K5: 100 000 hab. | L5: et plus | M5: de 10 000 hab. | N5: et plus | O5: communes
A7: DÉPENSES DE FONCTIONNEMENT (1) | B7: 1108.0961 | C7: 830.71594 | D7: 723.82328 | E7: 757.29401 | F7: 874.85198 | G7: 999.2405 | H7: 1108.4014 | I7: 1251.8403 | J7: 1397.6981 | K7: 1506.6052 | L7: 1776.8179 | M7: 897.02359 | N7: 1497.5041 | O7: 1202.0581
A8: Achats et charges externes | B8: 446.80232 | C8: 320.94096 | D8: 262.58186 | E8: 262.1971 | F8: 290.67268 | G8: 311.17744 | H8: 317.75594 | I8: 326.77315 | J8: 346.8318 | K8: 342.03474 | L8: 327.88867 | M8: 289.79887 | N8: 336.06081 | O8: 313.2992
A9: Frais de personnel | B9: 253.18022 | C9: 232.25157 | D9: 252.29625 | E9: 335.44694 | F9: 442.41073 | G9: 536.51583 | H9: 630.20958 | I9: 743.55735 | J9: 849.36035 | K9: 909.90978 | L9: 884.44201 | M9: 442.74932 | N9: 847.5394 | O9: 648.37623
A10: Charges financières | B10: 16.1494 | C10: 13.866573 | D10: 12.536208 | E10: 14.579043 | F10: 17.048237 | G10: 18.139735 | H10: 20.053753 | I10: 21.645543 | J10: 27.496298 | K10: 39.122249 | L10: 43.189457 | M10: 16.638721 | N10: 32.915827 | O10: 24.907231
A11: Dépenses d'intervention | B11: 138.5605 | C11: 115.29632 | D11: 110.99155 | E11: 81.146829 | F11: 77.440242 | G11: 88.094978 | H11: 102.49047 | I11: 124.85242 | J11: 140.37238 | K11: 175.14497 | L11: 479.41413 | M11: 90.582046 | N11: 243.43011 | O11: 168.22643
A12: Autres dépenses de fonctionnement | B12: 253.40368 | C12: 148.36052 | D12: 85.417417 | E12: 63.924093 | F12: 47.280097 | G12: 45.312518 | H12: 37.891653 | I12: 35.011867 | J12: 33.637316 | K12: 40.393491 | L12: 41.883619 | M12: 57.254634 | N12: 37.557951 | O12: 47.249033
A13: RECETTES DE FONCTIONNEMENT (2) | B13: 1536.0129 | C13: 1111.8311 | D13: 933.40548 | E13: 947.57305 | F13: 1079.8969 | G13: 1219.4899 | H13: 1321.0065 | I13: 1454.0912 | J13: 1605.2796 | K13: 1741.823 | L13: 1963.3254 | M13: 1104.5817 | N13: 1702.5464 | O13: 1408.3382
A14: Impôts et taxes | B14: 656.21642 | C14: 513.75233 | D14: 474.97783 | E14: 544.56195 | F14: 677.1878 | G14: 792.629 | H14: 883.70736 | I14: 987.71721 | J14: 1104.7639 | K14: 1196.9013 | L14: 1423.8473 | M14: 677.48675 | N14: 1190.0805 | O14: 937.8762
A15: - Impôts locaux | B15: 452.84973 | C15: 394.79575 | D15: 392.88382 | E15: 481.774 | F15: 610.54855 | G15: 704.66516 | H15: 780.09402 | I15: 870.24266 | J15: 1003.6272 | K15: 1064.8609 | L15: 1012.0905 | M15: 596.70905 | N15: 988.10322 | O15: 795.53104
A16: (dont : fiscalité reversée) | B16: 73.518939 | C16: 48.391684 | D16: 46.369711 | E16: 77.908474 | F16: 114.6559 | G16: 140.46196 | H16: 165.40325 | I16: 193.0724 | J16: 203.54522 | K16: 240.3534 | L16: 196.29019 | M16: 110.52661 | N16: 205.59357 | O16: 158.81911
A17: - Autres impôts et taxes | B17: 203.36669 | C17: 118.95658 | D17: 82.094013 | E17: 62.787948 | F17: 66.639254 | G17: 87.963836 | H17: 103.61334 | I17: 117.47455 | J17: 101.13669 | K17: 132.04039 | L17: 411.75688 | M17: 80.777694 | N17: 201.97729 | O17: 142.34516
A18: Concours de l'État | B18: 515.65493 | C18: 338.02301 | D18: 258.14289 | E18: 225.77543 | F18: 217.50275 | G18: 222.70162 | H18: 224.92262 | I18: 239.94441 | J18: 250.35431 | K18: 273.35978 | L18: 209.4692 | M18: 231.10073 | N18: 240.04662 | O18: 235.6451
... A44: Dette au 31 décembre (12) | B44: 646.56187 | C44: 582.36767 | D44: 507.75018 | E44: 571.03215 | F44: 651.68738 | G44: 720.89919 | H44: 762.92482 | I44: 804.2155 | J44: 986.26993 | K44: 1322.466 | L44: 1894.7108 | M44: 646.97805 | N44: 1274.7224 | O44: 965.86216
A45: Ratios (voir définitions en annexe 3)
A46: R1 : Dépenses réelles de fonctionnement (DRF) (b) / habitant | B46: 1107.3287 | C46: 830.379 | D46: 723.30617 | E46: 756.30938 | F46: 872.51853 | G46: 995.29116 | H46: 1103.4454 | I46: 1247.4549 | J46: 1394.2566 | K46: 1503.9634 | L46: 1775.1001 | M46: 894.49607 | N46: 1494.5092 | O46: 1199.2932
A47: R2 : Produit des impositions directes hors fiscalité reversée / habitant | B47: 439.65874 | C47: 374.84659 | D47: 376.48396 | E47: 419.33634 | F47: 495.05395 | G47: 562.32375 | H47: 613.43065 | I47: 674.81097 | J47: 796.75594 | K47: 830.04873 | L47: 898.25901 | M47: 494.32517 | N47: 806.32678 | O47: 652.81701
A48: R2 bis : Produit des impositions directes y compris fiscalité reversée / habitant | B48: 452.84973 | C48: 394.79575 | D48: 392.88382 | E48: 481.774 | F48: 610.54855 | G48: 704.66516 | H48: 780.09402 | I48: 870.24266 | J48: 1003.6272 | K48: 1064.8609 | L48: 1012.0905 | M48: 596.70905 | N48: 988.10322 | O48: 795.53104
A49: R3 : Recettes réelles de fonctionnement (RRF) / habitant | B49: 1536.0129 | C49: 1111.8311 | D49: 933.40548 | E49: 947.57305 | F49: 1079.8969 | G49: 1219.4899 | H49: 1321.0065 | I49: 1454.0912 | J49: 1605.2796 | K49: 1741.823 | L49: 1963.3254 | M49: 1104.5817 | N49: 1702.5464 | O49: 1408.3382
A50: R4 : Dépenses d'équipement brutes (c) / habitant | B50: 709.53128 | C50: 496.16267 | D50: 384.48944 | E50: 377.78503 | F50: 405.42179 | G50: 421.17888 | H50: 420.18482 | I50: 388.35153 | J50: 402.55259 | K50: 441.11602 | L50: 382.35309 | M50: 404.13414 | N50: 400.27498 | O50: 402.17375
A51: R5 : Dette / habitant | B51: 646.56187 | C51: 582.36767 | D51: 507.75018 | E51: 571.03215 | F51: 651.68738 | G51: 720.89919 | H51: 762.92482 | I51: 804.2155 | J51: 986.26993 | K51: 1322.466 | L51: 1894.7108 | M51: 646.97805 | N51: 1274.7224 | O51: 965.86216
A52: R6 : DGF / habitant | B52: 274.96603 | C52: 214.79947 | D52: 173.75505 | E52: 163.01047 | F52: 161.54805 | G52: 163.48149 | H52: 163.16549 | I52: 181.63553 | J52: 204.72187 | K52: 228.52022 | L52: 175.55012 | M52: 165.73702 | N52: 195.28509 | O52: 180.74697
A53: (a) Habitants comptés selon la population totale de l'Insee
A54: (b) Diminuées des travaux en régie.
A55: (c) C'est-à-dire y compris les travaux en régie, les travaux effectués d'office pour le compte de tiers, les opérations di'nvestissement sur établissements d'enseignement et les opérations sous mandat.
A56: Champ : France entière (France métropolitaine et DOM).
A57: Source : DGFiP-Comptes de gestion ; budgets principaux - opérations réelles. Calculs DGCL. Montants calculés hors gestion active de la dette. INSEE, Recensement de la population (population totale en 2024 - année de référence 2021).
A59: Liste des 11 ratios
A60: Pour les communes de 3 500 habitants et plus, les données synthétiques sur la situation financière de la collectivité, prévues par l’article L. 2313-1 du code général des collectivités territoriales (CGCT), comprennent 11 ratios définis à l’article R. 2313-1. Ces ratios sont aussi calculés pour les groupements à fiscalité propre, les départements (articles L. 3313-1 et R. 3313-1) et les régions (articles L. 4313-2 et R. 4313-1). Toutefois, le ratio 8, qui correspond au coefficient de mobilisation du potentiel fiscal, n’est plus calculé.
A62: À noter : pour la détermination des montants de dépenses ou recettes réelles de fonctionnement à retenir pour le calcul des ratios, les reversements de fiscalité liés au FNGIR et aux différents fonds de péréquation horizontale sont comptabilisés en moindres recettes.
A64: • Ratio 1 = dépenses réelles de fonctionnement (DRF) / population : montant total des dépenses de fonctionnement en mouvement réels. Les dépenses liées à des travaux en régie sont exclues des DRF.
A66: • Ratio 2 = produit des impositions directes / population : (recettes hors fiscalité reversée).
A68: • Ratio 2 bis = produit net des impositions directes / population : en plus des impositions directes, ce ratio intègre les prélèvements pour reversements de fiscalité et la fiscalité reversée aux communes par les groupements à fiscalité propre.
A70: • Ratio 3 = recettes réelles de fonctionnement (RRF) / population : montant total des recettes de fonctionnement en mouvements réels. Ressources dont dispose la collectivité, à comparer aux dépenses de fonctionnement dans leur rythme de croissance.
... A86: Les ratios 7 à 11 sont exprimés en pourcentage.

Sheet T 2.3
A1: T 2.3 - Évolution à champ constant (a) par strate de population des communes
O2: en %
A3: Evolutions 2024 / 2023 en % | B3: Moins | C3: De 100 | D3: De 200 | E3: De 500 | F3: De 2 000 | G3: De 3 500 | H3: De 5 000 | I3: De 10 000 | J3: De 20 000 | K3: De 50 000 | L3: 100000 | M3: Communes | N3: Communes | O3: Ensemble
B4: de 100 | C4: à moins de | D4: à moins de | E4: à moins de | F4: à moins de | G4: à moins de | H4: à moins de | I4: à moins de | J4: à moins de | K4: à moins de | L4: habitants | M4: de moins | N4: de 10 000 hab. | O4: des
A5: Hors gestion active de la dette | B5: habitants | C5: 200 hab. | D5: 500 hab. | E5: 2 000 hab. | F5: 3 500 hab. | G5: 5 000 hab. | H5: 10 000 hab. | I5: 20 000 hab. | J5: 50 000 hab. | K5: 100 000 hab. | L5: et plus | M5: de 10 000 hab. | N5: et plus | O5: communes
A7: DÉPENSES DE FONCTIONNEMENT (1) | B7: 4.6100856 | C7: 4.8977878 | D7: 5.0125776 | E7: 4.6936129 | F7: 4.4424634 | G7: 3.5155404 | H7: 3.9889944 | I7: 3.6466346 | J7: 3.1540938 | K7: 3.627244 | L7: 5.3359965 | M7: 4.2955539 | N7: 4.0847469 | O7: 4.1620653
A8: Achats et charges externes | B8: 6.4336699 | C8: 7.0924199 | D8: 7.1713984 | E8: 6.0000483 | F8: 4.6404008 | G8: 3.353362 | H8: 3.406772 | I8: 3.4393186 | J8: 2.3247435 | K8: 3.3255518 | L8: 5.2223946 | M8: 4.8055309 | N8: 3.562075 | O8: 4.124406
A9: Frais de personnel | B9: 3.8836793 | C9: 4.4745246 | D9: 4.3903661 | E9: 4.8849371 | F9: 5.1499875 | G9: 4.9081525 | H9: 4.3891233 | I9: 3.9405646 | J9: 3.5330309 | K9: 3.0771965 | L9: 5.4632195 | M9: 4.7225524 | N9: 4.1124521 | O9: 4.3167059
A10: Charges financières | B10: 17.125087 | C10: 12.03851 | D10: 11.353643 | E10: 6.9606478 | F10: 5.4956332 | G10: 5.4575541 | H10: 3.9433644 | I10: 8.0313274 | J10: 6.8154595 | K10: 12.233177 | L10: 14.822678 | M10: 5.9939665 | N10: 11.122901 | O10: 9.3827758
A11: Dépenses d'intervention | B11: 6.7800082 | C11: 4.1205624 | D11: 3.7492181 | E11: 5.3032026 | F11: 5.7456184 | G11: 4.6126 | H11: 4.432204 | I11: 3.5667759 | J11: 4.7742123 | K11: 4.6279636 | L11: 4.9963777 | M11: 4.8416545 | N11: 4.7498038 | O11: 4.7741205
A12: Autres dépenses de fonctionnement | B12: 0.47600774 | C12: 1.0434908 | D12: 1.2799354 | E12: -2.3663845 | F12: -4.916101 | G12: -11.84207 | H12: 1.1780929 | I12: -2.5596417 | J12: -6.332706 | K12: 6.743282 | L12: -1.110946 | M12: -2.4424305 | N12: -1.5750069 | O12: -2.0940267
A13: RECETTES DE FONCTIONNEMENT (2) | B13: 0.4744945 | C13: 2.1725028 | D13: 3.258756 | E13: 3.7016363 | F13: 4.1117775 | G13: 3.4790005 | H13: 3.6983833 | I13: 3.1171785 | J13: 2.7172115 | K13: 3.8322215 | L13: 1.7837631 | M13: 3.6416294 | N13: 2.6670261 | O13: 3.0409965
A14: Impôts et taxes | B14: -1.285355 | C14: 0.7563497 | D14: 2.7827501 | E14: 4.0785023 | F14: 4.1513335 | G14: 4.2077727 | H14: 3.4230463 | I14: 2.9979262 | J14: 2.5342541 | K14: 2.4361694 | L14: 0.76346247 | M14: 3.7155912 | N14: 1.9644064 | O14: 2.5801111
A15: - Impôts locaux | B15: 6.0440669 | C15: 5.3809798 | D15: 6.2170425 | E15: 6.0609412 | F15: 5.8364998 | G15: 6.0530797 | H15: 4.8485256 | I15: 4.2480123 | J15: 3.7521005 | K15: 3.346697 | L15: 3.3018952 | M15: 5.6157563 | N15: 3.6319344 | O15: 4.3555071
A16: (dont : fiscalité reversée) | B16: 4.7301984 | C16: 2.8238101 | D16: 3.6477088 | E16: 1.7691972 | F16: 1.7676999 | G16: 1.6744694 | H16: -0.21604584 | I16: 0.4689909 | J16: 0.037405332 | K16: -0.90880117 | L16: 3.0503434 | M16: 1.088374 | N16: 0.76071335 | O16: 0.87263978
A17: - Autres impôts et taxes | B17: -14.451799 | C17: -12.052812 | D17: -10.990043 | E17: -8.9721285 | F17: -9.1067647 | G17: -8.5341333 | H17: -6.1803262 | I17: -5.4051133 | J17: -8.1529419 | K17: -4.3593864 | L17: -4.975974 | M17: -8.4488048 | N17: -5.471767 | O17: -6.3222695
